Workbook
Name \a: [1]GENERAL!#REF!
Name \a: [2]GENERAL!#REF!
Name \a: [1]GENERAL!#REF!
Name \a: [1]GENERAL!#REF!
Name \ac: [1]GENERAL!#REF!
Name \ac: [2]GENERAL!#REF!
Name \ac: [1]GENERAL!#REF!
Name \ac: [1]GENERAL!#REF!
Name \b: [1]GENERAL!#REF!
Name \b: [2]GENERAL!#REF!
Name \b: [1]GENERAL!#REF!
Name \b: [1]GENERAL!#REF!
Name \c: [1]GENERAL!#REF!
Name \c: [2]GENERAL!#REF!
Name \c: [1]GENERAL!#REF!
Name \c: [1]GENERAL!#REF!
Name \f: [1]GENERAL!#REF!
Name \f: [2]GENERAL!#REF!
Name \f: [1]GENERAL!#REF!
Name \f: [1]GENERAL!#REF!
Name \h: [2]GENERAL!#REF!
Name \h: [1]GENERAL!#REF!
Name \M: [3]B!$Q$2
Name \M: [4]B!$Q$2
Name \p: [2]GENERAL!$GV$8084
Name \p: [1]GENERAL!$GV$8084
Name \r: [2]GENERAL!#REF!
Name \r: [1]GENERAL!#REF!
Name \t: [2]GENERAL!#REF!
Name \t: [1]GENERAL!#REF!
Name \w: [2]GENERAL!#REF!
Name \w: [1]GENERAL!#REF!
Name \x: [2]GENERAL!#REF!
Name \x: [1]GENERAL!#REF!
Name _500_AREA_TOTAL_LBCu: '[5]Plant Operating Expenses'!#REF!
Name _500_AREA_TOTAL_LBCu: '[6]Plant Operating Expenses'!#REF!
Name _500_AREA_TOTAL_LBCu: '[5]Plant Operating Expenses'!#REF!
Name _500_AREA_TOTAL_LBCu: '[5]Plant Operating Expenses'!#REF!
Name _500_DIESEL_FUEL: '[5]Plant Operating Expenses'!#REF!
Name _500_DIESEL_FUEL: '[6]Plant Operating Expenses'!#REF!
Name _500_DIESEL_FUEL: '[5]Plant Operating Expenses'!#REF!
Name _500_DIESEL_FUEL: '[5]Plant Operating Expenses'!#REF!
Name _500_MAINTENANCE_SUPPLIES: '[5]Plant Operating Expenses'!#REF!
Name _500_MAINTENANCE_SUPPLIES: '[6]Plant Operating Expenses'!#REF!
Name _500_MAINTENANCE_SUPPLIES: '[5]Plant Operating Expenses'!#REF!
Name _500_MAINTENANCE_SUPPLIES: '[5]Plant Operating Expenses'!#REF!
Name _500_PERSONNEL: '[5]Plant Operating Expenses'!#REF!
Name _500_PERSONNEL: '[6]Plant Operating Expenses'!#REF!
Name _500_PERSONNEL: '[5]Plant Operating Expenses'!#REF!
Name _500_PERSONNEL: '[5]Plant Operating Expenses'!#REF!
Name _600_AREA_TOTAL_LBCu: '[5]Plant Operating Expenses'!#REF!
Name _600_AREA_TOTAL_LBCu: '[6]Plant Operating Expenses'!#REF!
Name _600_AREA_TOTAL_LBCu: '[5]Plant Operating Expenses'!#REF!
Name _600_AREA_TOTAL_LBCu: '[5]Plant Operating Expenses'!#REF!
Name _600_CATHODE_TRANSPORT: '[6]Plant Operating Expenses'!#REF!
Name _600_CATHODE_TRANSPORT: '[5]Plant Operating Expenses'!#REF!
Name _600_ELECTRICAL_POWER: '[6]Plant Operating Expenses'!#REF!
Name _600_ELECTRICAL_POWER: '[5]Plant Operating Expenses'!#REF!
Name _600_MAINTENANCE_SERVICES_CONTRACT: '[6]Plant Operating Expenses'!#REF!
Name _600_MAINTENANCE_SERVICES_CONTRACT: '[5]Plant Operating Expenses'!#REF!

Sheet EVALUACION RESSO EECC
I1: Fecha: MARZO 2026
I2: Versión: 00
B3: LISTA DE VERIFICACIÓN EVALUACIÓN SGSST
B6: DIVISIÓN: | D6: Chuquicamata
B7: GERENCIA: | D7: GERENCIA MANTENIMIENTO MINA CHUQUICAMATA SUBTERRÁNEA
B8: SUPERINTENDENCIA / DIRECCIÓN: | D8: GERENCIA MANTENIMIENTO MINA CHUQUICAMATA SUBTERRÁNEA
B9: NOMBRE DE LA EMPRESA: | D9: TRANSMACLTDA
B10: NOMBRE DEL SERVICIO Y N° DE CONTRATO: | D10: “SERVICIO DE ARRIENDO DE GRUA PLUMA 250 TON Y CAMA BAJA CON OPERACIÓN”
B11: NUMERO DE CONTRATO: | D11: 4600030845
B12: ADMINISTRADO DE CONTRATO EECC.: | D12: CARLA BRICEÑO G
B13: APR EECC: | D13: DARWIN SOTO H
B14: ADMINISTRADOR DE CONTRATO CODELCO: | D14: PATRICIO BARRIENTOS L
B15: JEFE SEGURIDAD ÁREA CODELCO: | D15: ANDRES ILLANES L
B16: FECHA: | D16: =TODAY() -> 46113
B18: CUMPLIMIENTO TOTAL AUDITORÍA | G18: =IF(COUNT(G69:I70)>0,AVERAGE(G69:I70),"N/A")-D50 -> 0.94756944
B20: CANTIDAD DE HALLAZGOS DOCUMENTAL
B21: NO CONFORMIDAD | D21: 0
B22: OBSERVACIÓN | D22: =COUNTIF(' HALLAZGOS DOC RESSO'!E10:E37,"OBS") -> 0
B23: OPORTUNIDAD DE MEJORA | D23: =COUNTIF(' HALLAZGOS DOC RESSO'!E10:E37,"OM") -> 0
B25: CANTIDAD DE HALLAZGOS TERRENO
B26: NIVEL 1 | D26: 0 | E26: =D26*0.05 -> 0
B27: NIVEL 2 | D27: 0 | E27: =D27*0.001 -> 0
E28: =D28*0.005 -> 0
E29: =D29*0.005 -> 0
E30: =D30*0.005 -> 0
E31: =D31*0.005 -> 0
E32: =D32*0.005 -> 0
E33: =D33*0.005 -> 0
E34: =D34*0.005 -> 0
E35: =D35*0.005 -> 0
E36: =D36*0.005 -> 0
E37: =D37*0.005 -> 0
E38: =D38*0.005 -> 0
E39: =D39*0.005 -> 0
... E47: =D47*0.005 -> 0
B48: OPORTUNIDAD DE MEJORA TERRENO | D48: 0 | E48: =D48*0.005 -> 0
B49: OBSERVACIÓN POSITIVA | D49: 0 | E49: =D49*0.005 -> 0
B50: TOTAL % DESC. AUDITORÍA TERRENO | D50: =SUM(E26:E49) -> 0 | E50: =SUM(E26:E49) -> 0
B52: * Toda empresa que es considerada con un nivel de exposición “Inaceptable” tendrá un plazo de una semana para regularizar y llevar a nivel moderado su gestión. De no conseguir esta condición se detendrá toda tarea asociada a la Empresa Contratista hasta conseguir los niveles exigidos (a costo de la empresa contratista o subcontratista). * Toda empresa con un nivel de exposición “moderado” tendrá un plazo de un mes para resolver las observaciones de las auditorías. De no cumplir o de volver a obtener un nivel “moderado” será considerada como una empresa de “desempeño discreto” en gestión, en caso de tener una tercera evaluación consecutiva de “moderado” será considerada como empresa de desempeño “inaceptable” y se someterá al proceso de sanción de Abastecimiento. (Que podría llegar hasta una suspensión de 1 año de participación en licitaciones Corporativas)
B62: Firma Adm. Ctto EECC Firma APR EECC
...

Sheet PLAN DE ACCION RESSO 
A1: PLAN DE ACCION RESSO MARZO 2026
A2: ÍTEM | B2: REQUISITO | G2: Modo de cumplimiento | K2: EVIDENCIA | L2: RESPONSABLE | M2: FECHA DE CUMPLIMIENTO
A3: 3 | B3: ¿Esta Política Corporativa se dio a conocer a todos los trabajadores de la contratista y subcontratistas? Se cuenta con evidencia de ello? | H3: Difusion y evaluación de la polictica de forma mensual | K3: Registro de difusipon y evaluacion a todo el personal del contrato | L3: EXPERTO PREVENCION DE RIESGOS // ADC | M3: 46111
A4: 8 | B4: ¿La empresa cuenta con la identificación de los GES (Grupo de Exposición Similar), con listado de expuestos y Programa de Vigilancia Medica, en coordinación con el organismo administrador del seguro? ¿Cumple con las medidas prescritas emitidas por el organismo administrador? | H4: Identificación de la GES | K4: GES | L4: EXPERTO PREVENCION DE RIESGOS // ADC | M4: 46111
A5: 9 | B5: ¿Cuenta la empresa contratista con Mapas de Riesgo de Higiene Industrial en el lugar donde realiza sus actividades?, a partir de éstos, ¿se cuenta con un programa de gestión, con responsables, acciones y fechas? ¿Realizo difusión del mapa de riesgo a los trabajadores (as)? | H5: Confeccion mapa de riesgos, difusion y evaluacion | K5: MAPA DE RIESGOS DIFUNDIDO | L5: EXPERTO PREVENCION DE RIESGOS // ADC | M5: 46111
A6: 11 | B6: ¿Tiene identificado, documentado y evaluado los requisitos de los “EST” que aplican a sus procesos o servicios y cuenta con plan de brechas, si aplica? | H6: Listas de verificacion EST | K6: Dar cumplimiento a brechas | L6: EXPERTO PREVENCION DE RIESGOS // ADC | M6: 46142
A7: 12 | B7: ¿Se cumple y se dispone de evidencias de las actividades definidas en el “Estándar de Liderazgo”, de acuerdo a lo programado? | H7: Incoporrar el PAM | K7: PAM | L7: EXPERTO PREVENCION DE RIESGOS // ADC | M7: 46068
A8: 13 | B8: Se cumple y se dispone de evidencias de actividades definidas en el “Estándar de Seguridad Conductual” de acuerdo a lo programado (N° Observadores, cierre de ciclo, conductas preocupantes y plan de acción)? | H8: Observaciones conductuales de acuerdo a plan de liderazgo | K8: Plan conductual he informe | L8: EXPERTO PREVENCION DE RIESGOS // ADC | M8: Mnesual
A9: 16 | B9: ¿La empresa cuenta con un plan de emergencia formal que considere la comunicación, coordinación y plan de acción ante una emergencia que le afecte y se difundió a sus trabajadores (as)? | H9: Difusion y evaluacion | K9: Registro de difusion y evaluacion | L9: EXPERTO PREVENCION DE RIESGOS // ADC | M9: 46111
A10: 18 | B10: ¿La empresa contratista capacita a sus trabajadores, supervisores y línea de mando respecto de los planes de emergencia de Codelco y propios, de las áreas donde ejecutaran sus actividades? | H10: Difusion y evaluacion | K10: Registro de difusion y evaluacion | L10: EXPERTO PREVENCION DE RIESGOS // ADC | M10: 46111
A11: 19 | B11: ¿La empresa contratista evaluó los riesgos de un potencial accidente grave o fatal considerando los Riesgos Críticos aplicables (Bowtie) y ECF identificados y de las tareas críticas? ¿De lo anterior se realizó un simulacro documental, implementando las medidas correctivas y preventivas dentro de los plazos definidos? | H11: Aplicación de simulacro fatal | K11: Implememtacion F7 | L11: EXPERTO PREVENCION DE RIESGOS // ADC | M11: 46142
A12: 34 | B12: ¿Cuenta la empresa con personal capacitado en el método para investigar incidentes definido por Codelco (EVITA/RDP 8 pasosy/o 3 pasos)? | H12: Capacitacion por parte de la mandante | K12: Registro capacitacion | L12: EXPERTO PREVENCION DE RIESGOS // ADC | M12: 46142

Sheet Implementacion SIGO
AE2: 1
AE3: 0.95
AE4: 0.9
B5: I. REQUERIMIENTOS PARA IMPLEMENTAR UN SIGO PARA EMPRESAS CONTRATISTAS Y SUBCONTRATISTAS DE CODELCO. | AE5: 0.85
AE6: 0.8
B7: A. SISTEMA DE GESTION DE SEGURIDAD Y SALUD EN EL TRABAJO (TITULO IV) | D7: CUMPLIMIENTO | AE7: 0.75
B8: 1. | C8: ¿Cuenta la empresa contratista con un sistema de gestión de Seguridad y Salud en el Trabajo, certificado en la norma OHSAS 18.001 o ISO 45001, asociada al alcance de la obra o servicios prestados específicamente a la división o VP? | D8: 1 | AE8: 0.7
B9: Comentarios: | AE9: 0.65
AE10: 0.6
AE11: 0.55
AE12: 0.5
AE13: 0.45
B14: B. PROGRAMA DE SEGURIDAD Y SALUD EN EL TRABAJO (TITULO V RESSO) | D14: CUMPLIMIENTO | AE14: 0.4
B15: B.1 Contenidos del Programa de Seguridad y Salud en el Trabajo | AE15: 0.35
B16: 2. | C16: ¿En la elaboración del Programa de Seguridad y Salud en el Trabajo de la empresa, se consideró los enunciados de la Política Corporativa de Gestión de Seguridad, Salud en el Trabajo y Riesgos Operacionales de Codelco (Descrita en el Título I RESSO V9)? | D16: 1 | AE16: 0.3
B17: 3. | C17: ¿Esta Política Corporativa se dio a conocer a todos los trabajadores de la contratista y subcontratistas? ¿Se cuenta con evidencia de ello? | D17: 0.5 | AE17: 0.25
B18: B.2 Elementos del Programa (Establecimiento de objetivos y metas) | AE18: 0.2
B19: 4. | C19: ¿El programa definido para el cumplimiento de los objetivos y metas consistentes en la política de seguridad y salud ocupacional, cuenta con indicadores de desempeño, responsables, recursos y plazos consistentes con la criticidad de las actividades definidas, así como también con los 7 Elementos del Sistema de Gestión de Seguridad y Salud en el Trabajo u Ocupacional de CODELCO | D19: 1 | AE19: 0.15
B20: B.3 Planificación y Administración del Sistema de Gestión (Identificación y cumplimiento del marco regulatorio) | AE20: 0.1
B21: 5. | C21: ¿La empresa cuenta con una metodología formal para la identificación y evaluación del marco regulatorio legal que aplica a sus procesos identificando nivel de cumplimiento, programas de brechas y monitoreo? | D21: 1 | AE21: 0.05
B22: B.4 Planificación y Administración del Sistema de Gestión (Proceso de identificación de Peligros, Evaluación y Control de Riesgos) | AE22: 0
B23: 6. | C23: ¿El programa de seguridad cuenta con un registro de identificación de peligros y la evaluación de riesgos actualizado acorde a las actividades del contrato y está en concordancia con la Carta Gantt del contrato? | D23: 1 | AE23: N/A
B24: 7. | C24: ¿El programa de SST cuenta con la validación previa, por parte del organismo Administrador del seguro correspondiente? ¿Además, está suscrito por el representante legal y por el administrador de la empresa contratista? | D24: 1
B25: 8. | C25: ¿La empresa cuenta con la identificación de los GES (Grupo de Exposición Similar), con listado de expuestos y Programa de Vigilancia Medica, en coordinación con el organismo administrador del seguro? ¿Cumple con las medidas prescritas emitidas por el organismo administrador? | D25: 0
B26: 9. | C26: ¿Cuenta la empresa contratista con Mapas de Riesgo de Higiene Industrial en el lugar donde realiza sus actividades?, a partir de éstos, ¿se cuenta con un programa de gestión, con responsables, acciones y fechas? ¿Realizo difusión del mapa de riesgo a los trabajadores? | D26: 0
B27: B.5 Estandarización de los controles operacionales
B28: 10. | C28: ¿Tienen identificados, documentados y evaluados los niveles de cumplimiento de los “Riesgos Críticos aplicables (Bowtie) y ECF” que aplican a sus procesos o servicios y cuentan con plan de brechas, si aplica? | D28: 1
B29: 11. | C29: ¿Tiene identificado, documentado y evaluado los requisitos de los “EST” que aplican a sus procesos o servicios y cuenta con plan de brechas, si aplica? | D29: 0.5
B30: 12. | C30: 3. ¿Se cumple y se dispone de evidencias de las actividades definidas en el “¿Estándar de Liderazgo”, de acuerdo a lo programado? | D30: 0.5
B31: 13. | C31: ¿Se cumple y se dispone de evidencias de actividades definidas en el “Estándar de Seguridad Conductual” de acuerdo a lo programado (Nº Observadores, cierre de ciclo, conductas preocupantes y plan de acción)? | D31: 0.5
B32: 14. | C32: ¿Respecto al “Estándar de Aprendizaje”. ¿Se difunden los reportes de incidentes Divisionales y Corporativos, en especial los que apliquen a su servicio? Si aplica, ¿la empresa realiza una evaluación de la probabilidad de ocurrencia del incidente y de los controles existentes en su área de responsabilidad? | D32: 1
B33: 15. | C33: ¿De los incidentes del contrato (Evento Significativo, CTP o STP), se ha realizado la investigación respectiva, las medidas correctivas y preventivas se encuentran cerradas dentro del plazo de acuerdo a la investigación y se privilegia la definición de medidas de control de alta jerarquía?. ¿Estas medidas fueron verificadas en terreno? | D33: N/A
B34: B.6 Preparación y Respuesta ante emergencias
B35: 16. | C35: ¿La empresa cuenta con un plan de emergencia formal que considere la comunicación, coordinación y plan de acción ante una emergencia que le afecte y se difundió a sus trabajadores? | D35: 0.5
B36: 17. | C36: ¿La empresa cuenta con un programa de simulacros relacionados a emergencias que afecten a su servicio? | D36: 1
B37: 18. | C37: ¿La empresa contratista capacita a sus trabajadores, supervisores y línea de mando respecto de los planes de emergencia de Codelco y propios, de las áreas donde ejecutaran sus actividades? | D37: 0.5
B38: 19. | C38: ¿La empresa contratista evaluó los riesgos de un potencial accidente grave o fatal considerando los Riesgos Críticos aplicables (Bowtie) y ECF identificados y de las tareas críticas? ¿De lo anterior se realizó un simulacro documental, implementando las medidas correctivas y preventivas dentro de los plazos definidos? | D38: 0
B39: Comentarios:
B44: C. Implementación y Operación (Título VI RESSO) | D44: CUMPLIMIENTO
B45: C.1 Obligación de Informar
...

Sheet Implementacion y Operacion
AF3: 1
AF4: 0.95
B5: II. Requerimientos para la Implementación y Operación (Otros Requisitos Relevantes del SIGO) | AF5: 0.9
AF6: 0.85
B7: G. Medidas de Prevención Especiales (Título XI RESSO) | D7: CUMPLIMIENTO | AF7: 0.8
B8: G.1 Aviso escrito | AF8: 0.75
B9: 39. | C9: ¿La empresa informa a través del Libro de Obras o Libro de Obra Digital o Cartas Contractuales al Administrador de Contrato Codelco respecto de los trabajos que implican riesgos inherentes altos, indicando los métodos seguros para realizar sus tareas críticas? | D9: 1 | AF9: 0.7
B10: Comentarios | AF10: 0.65
AF11: 0.6
AF12: 0.55
AF13: 0.5
AF14: 0.45
B15: H. Estándares Mínimos (Título XII RESSO) | D15: CUMPLIMIENTO | AF15: 0.4
B16: H.1 Estándares Corporativos | AF16: 0.35
B17: 40. | C17: ¿Existe registro formal de “Reunión de Inicio”, adecuadamente firmado, donde acrediten la entrega de los documentos estipulados por las Divisiones de Codelco/VP y en especial el RESSO a la empresa contratista y por extensión a los subcontratistas? | D17: 1 | AF17: 0.3
B18: 41. | C18: ¿Existe registro formal de “Reunión de Arranque”, adecuadamente firmado, donde acrediten la entrega de los documentos estipulados por las Divisiones de Codelco/VP, incluyendo la declaración de los subcontratos, toma de conocimiento del RESSO, de la empresa contratista y por extensión a los subcontratistas? | D18: 1 | AF18: 0.25
B19: Comentarios | AF19: 0.2
AF20: 0.15
AF21: 0.1
AF22: 0.05
AF23: 0
B24: I. Comités Paritarios de Higiene y Seguridad (Título XIII RESSO) | D24: CUMPLIMIENTO | AF24: N/A
B25: ¿Se cumple el programa de trabajo de los comités paritarios considerando las actas y los 7 puntos legales descritos en la legislación Art 24 DS N°54 y DS N° 76?
B26: 42. | C26: ¿Se cumple el programa de trabajo de los comités paritarios considerando las actas y los 7 puntos legales descritos en la legislación Art 24 DS N°54 y DS N° 76? | D26: N/A
B27: Comentarios
B33: J. Estadística e Información (Título XIV RESSO) | D33: CUMPLIMIENTO
B34: 43. | C34: ¿La empresa cumple con la exigencia de entregar el informe requerido una vez por mes en la fecha requerida y los datos referente al cumplimiento de las actividades impresas en él son concordante, con la información existente en el área de trabajo? (EJ: Actividades de Liderazgo Preventivo y autoevaluaciones del RESSO, etc.) | D34: 1
B35: 44. | C35: ¿La empresa entrega las estadísticas de información de riesgos profesionales en los formatos y plazos requeridos por Codelco? | D35: 1
B36: Comentarios
B41: K. Infracciones o Faltas de los Contratistas / Trabajadores al RIHS (TITULO XV y XVI) | D41: CUMPLIMIENTO
B42: 45. | C42: ¿Cuenta la empresa con un plan de difusión, capacitación y evaluación para que sus trabajadores, supervisores y línea de mando cumplan y conozcan el proceder ante faltas menores, graves e infracciones de los contratistas o subcontratistas y de los trabajadores indicadas en el título XV y XVI del RESSO? | D42: 1
B43: Comentarios

Sheet COMENTARIOS
B6: COMENTARIOS
B8: I. REQUERIMIENTOS PARA IMPLEMENTAR UN SIGO PARA EMPRESAS CONTRATISTAS Y SUBCONTRATISTAS DE CODELCO.
B10: A. SISTEMA DE GESTIÓN DE SEGURIDAD Y SALUD EN EL TRABAJO
B17: B. PROGRAMA DE SEGURIDAD Y SALUD EN EL TRABAJO
B25: C. IMPLEMENTACIÓN Y OPERACIÓN
B33: D. RESULTADOS DE FISCALIZACIONES INTERNAS Y EXTERNAS
B41: E. PROCEDIMIENTOS EN CASO DE ACCIDENTES E INCIDENTES
B49: F. OBLIGACIONES Y PROHIBICIONES DE LAS EMPRESAS CONTRATISTAS Y SUBCONTRATISTAS
B58: II. REQUERIMIENTOS PARA LA IMPLEMENTACIÓN Y OPERACIÓN
B59: G. MEDIDAS DE PREVENCIÓN ESPECIALES
B67: H. ESTÁNDARES MÍNIMOS
B75: I. COMITÉS PARITARIOS DE HIGIENE Y SEGURIDAD
... B91: K. INFRACCIONES O FALTAS DE LOS CONTRATISTAS O SUBCONTRATISTAS

Sheet  HALLAZGOS DOC RESSO
B6: RESUMEN DE HALLAZGOS DOCUMENTAL RESSO
B8: I. REQUERIMIENTOS PARA IMPLEMENTAR UN SIGO PARA EMPRESAS CONTRATISTAS Y SUBCONTRATISTAS DE CODELCO.
B10: PUNTO RESSO | C10: DESCRIPCIÓN DEL HALLAZGO | D10: EVIDENCIA HALLAZGO (ANTES) | E10: CALIFICACIÓN DEL HALLAZGO | AC10: OM
AC11: OBS
AC12: NC
B23: II. Requerimientos para la Implementación y Operación (Otros Requisitos Relevantes del SIGO)
B25: PUNTO RESSO | C25: DESCRIPCIÓN DEL HALLAZGO | D25: EVIDENCIA HALLAZGO (ANTES) | E25: CALIFICACIÓN DEL HALLAZGO

Sheet VERIFICACIÓN EN TERRENO
I4: 1
I5: 0
B6: LISTA DE VERIFICACIÓN RESSO EN TERRENO | I6: N/A
B8: N° | C8: ITEM A EVALUAR | F8: CUMPLIMIENTO (%)
B9: 1 | C9: PLANIFICACIÓN DE LA TAREA.
B10: 1.1 | C10: Realización del análisis de riesgos de la tarea (ART). | F10: 1
C11: Se ha realizado el ART en terreno antes de la actividad. | F11: 1
C12: Cuenta con la participación de los trabajadores. | F12: 1 | X12: 1
C13: Es revisado por el supervisor. | F13: 1 | X13: 0.75
C14: Se han implementado las medidas de control identificadas. | F14: 1 | X14: 0.5
B15: 1.2 | C15: Se realiza Permiso Especial de Trabajo (Si aplica). | F15: 1 | X15: 0.25
B16: 1.3 | C16: Personal cuenta y utiliza los EPP exigidos por el área. | F16: 1 | X16: 0
B17: 1.4 | C17: Se encuentra el área segregada / delimitada. | F17: 1 | X17: N/A
B18: 1.5 | C18: Se identifican interacciones con otros trabajos en el área. | F18: 1
B19: 2 | C19: AISLACIÓN Y BLOQUEO.
B20: 2.1 | C20: Se realiza bloqueo personal de equipo, maquina, sistema. | F20: N/A
B21: 2.2 | C21: Elementos de bloqueo en buen estado, personales e identificados. | F21: N/A
B22: 3 | C22: TRABAJOS EN ALTURA FÍSICA.
B23: 3.1 | C23: Personal cuenta con autorización. | F23: 1
B24: 3.2 | C24: Plataforma de trabajo cuenta con registro de inspección. | F24: 1
B25: 3.3 | C25: Herramientas, equipos y elementos cuentan con sistemas que eviten su caída desde altura. | F25: 1
B26: 3.4 | C26: Se cuenta con puntos de anclaje certificados. | F26: 1
B27: 3.5 | C27: Se cuenta con certificados, inspeccionados, y con código de color correspondiente. | F27: 1
B28: 4 | C28: EQUIPOS Y HERRAMIENTAS PORTÁTILES Y MANUALES.
B29: 4.1 | C29: Herramientas se encuentran en buen estado, con código de color de inspección del mes. | F29: N/A
B30: 4.2 | C30: Herramientas eléctricas se encuentran aisladas, en buen estado. | F30: N/A
B31: 4.3 | C31: Equipos y Herramientas cuentan con sistema de hombre muerto. | F31: N/A
B32: 5 | C32: CARGAS SUSPENDIDAS E IZAJE.
B33: 5.1 | C33: Se cuenta con plan de izaje / procedimiento. | F33: 1
B34: 5.2 | C34: Elementos de izaje en buen estado, inspeccionado y con código de color correspondiente. | F34: 1
B35: 6 | C35: MANEJO SUSTANCIAS PELIGROSAS.
B36: 6.1 | C36: Se cuenta con hoja de datos de seguridad. | F36: N/A
B37: 6.2 | C37: Contenedores Originales o de re envase rotulados. | F37: N/A
B38: 7 | C38: VEHÍCULOS LIVIANOS / EQUIPOS PESADOS.
B39: 7.1 | C39: Operador o conductor cuenta con licencia respectiva. | F39: 1
B40: 7.2 | C40: Se realiza Lista Chequeo del vehículo / Encuesta Fatiga y Somnolencia. | F40: 1
B41: 7.3 | C41: Se cuenta con plan de tránsito. | F41: 1
B42: 7.4 | C42: Existe segregación equipo - persona en la actividad. | F42: N/A
B43: 8 | C43: INCENDIO.
B44: 8.1 | C44: Se cuenta con equipos en buen estado y procedimiento en caso de emergencia. | F44: 1
...

Sheet HALLAZGO EN TERRENO
AL5: NIVEL 1
B6: RESUMEN DE HALLAZGOS EN TERRENO | AL6: NIVEL 2
AL7: OM
B8: N° | C8: DESCRIPCIÓN DEL HALLAZGO | D8: EVIDENCIA HALLAZGO (ANTES) | E8: CALIFICACIÓN DEL HALLAZGO | AL8: OBPOS
B9: 1
B10: 2 | C10: xz<xz<xz< | D10: HFGH | E10: NIVEL 1
B11: 3 | C11: DFHFSHFHF | D11: FHFGHF | E11: NIVEL 2
B12: 4 | C12: DFGDFHDFHF | D12: HFH | E12: OM
B13: 5 | C13: FHFGHFGJH | D13: HFGHFD | E13: OBPOS
B14: 6 | C14: HFGHFGJ | D14: HFGHFGH | E14: NIVEL 2
B15: 7
B16: 8
B17: 9
B18: 10
B19: 11
B20: 12
B21: 13
B22: 14
B23: 15
B24: 16
B25: 17
B26: 18
... B28: 20

Sheet GRÁFICO 
AK3: ='EVALUACION RESSO EECC'!B71 -> I. REQUERIMIENTOS PARA IMPLEMENTAR UN SIGO PARA EMPRESAS CONTRATISTAS Y SUBCONTRATISTAS DE CODELCO
AK4: ='EVALUACION RESSO EECC'!B72 -> A. SISTEMA DE GESTION DE SEGURIDAD Y SALUD EN EL TRABAJO (TITULO IV) | AL4: ='EVALUACION RESSO EECC'!G72 -> 1
AK5: ='EVALUACION RESSO EECC'!B73 -> B. PROGRAMA DE SEGURIDAD Y SALUD EN EL TRABAJO (TITULO V RESSO) | AL5: ='EVALUACION RESSO EECC'!G73 -> 0.74166667
AK6: ='EVALUACION RESSO EECC'!B74 -> B.1 Contenidos del Programa de Seguridad y Salud en el Trabajo | AL6: ='EVALUACION RESSO EECC'!G74 -> 0.75
AK7: ='EVALUACION RESSO EECC'!B75 -> B.2 Elementos del Programa (Establecimiento de objetivos y metas) | AL7: ='EVALUACION RESSO EECC'!G75 -> 1
AK8: ='EVALUACION RESSO EECC'!B76 -> B.3 Planificación y Administración del Sistema de Gestión (Identificación y cumplimiento del marco regulatorio) | AL8: ='EVALUACION RESSO EECC'!G76 -> 1
AK9: ='EVALUACION RESSO EECC'!B77 -> B.4 Planificación y Administración del Sistema de Gestión (Proceso de identificación de Peligros, Evaluación y Control de Riesgos) | AL9: ='EVALUACION RESSO EECC'!G77 -> 0.5
AK10: ='EVALUACION RESSO EECC'!B78 -> B.5 Estandarización de los controles operacionales | AL10: ='EVALUACION RESSO EECC'!G78 -> 0.7
AK11: ='EVALUACION RESSO EECC'!B79 -> B.6 Preparación y Respuesta ante emergencias | AL11: ='EVALUACION RESSO EECC'!G79 -> 0.5
AK12: ='EVALUACION RESSO EECC'!B80 -> C. IMPLEMENTACION Y OPERACIÓN (TITULO VI RESSO) | AL12: ='EVALUACION RESSO EECC'!G80 -> 1
AK13: ='EVALUACION RESSO EECC'!B81 -> C.1 Obligación de Informar / ODI | AL13: ='EVALUACION RESSO EECC'!G81 -> 1
AK14: ='EVALUACION RESSO EECC'!B82 -> C.2 Participación de los trabajadores | AL14: ='EVALUACION RESSO EECC'!G82 -> 1
AK15: ='EVALUACION RESSO EECC'!B83 -> C.3 Documentación que debe mantener la empresa principal. | AL15: ='EVALUACION RESSO EECC'!G83 -> 1
... AK23: ='EVALUACION RESSO EECC'!B91 -> E. PROCEDIMIENTOS EN CASO DE ACCIDENTES E INCIDENTES (TITULO VIII RESSO) | AL23: ='EVALUACION RESSO EECC'!G91 -> 0
AK24: ='EVALUACION RESSO EECC'!B92 -> E.1 Informe de Accidentes Graves, Fatales y de Alto Potencial | AL24: ='EVALUACION RESSO EECC'!G91 -> 0
AK25: ='EVALUACION RESSO EECC'!B93 -> F. OBLIGACIONES DE LAS EMPRESASCONTRATISTAS Y SUBCONTRATISTAS (Título IX Y X RESSO) | AL25: ='EVALUACION RESSO EECC'!G93 -> 1
AK27: ='EVALUACION RESSO EECC'!B94 -> II. REQUERIMIENTOS PARA LA IMPLEMENTACIÓN Y OPERACIÓN (OTROS REQUISITOS RELEVANTES DEL SIGO)
AK28: ='EVALUACION RESSO EECC'!B95 -> G. Medidas de Prevención Especiales (Título XI RESSO) | AL28: ='EVALUACION RESSO EECC'!G95 -> 1
AK29: ='EVALUACION RESSO EECC'!B97 -> H. Estándares Mínimos (Título XII RESSO) | AL29: ='EVALUACION RESSO EECC'!G97 -> 1
AK30: ='EVALUACION RESSO EECC'!B99 -> I. Comités Paritarios de Higiene y Seguridad (Título XIII RESSO) | AL30: ='EVALUACION RESSO EECC'!G99 -> N/A
AK31: ='EVALUACION RESSO EECC'!B101 -> J. Estadística e Información (Título XIV RESSO) | AL31: ='EVALUACION RESSO EECC'!G101 -> 1
AK32: ='EVALUACION RESSO EECC'!B102 -> K. Infracciones o Faltas de los Contratistas / Trabajadores al RIHS (TITULO XV y XVI) | AL32: ='EVALUACION RESSO EECC'!G102 -> 1
